Workbook

Sheet Read Me
A1: HR Health Check | risk and action build pack
A2: V3 develops the existing workbook rather than replacing its structure. The customer sees a clear assessment and action plan; the additional detail is the controlled content and logic behind it.
A3: DREAMSTONEHR | PROPOSED V3.0 | 10 OCTOBER 2026
A5: Section | B5: Decision / guidance | C5: Where to work
A6: Purpose | B6: A paid, self-reported HR decision-support assessment for businesses with 5-200 employees. Give a useful plan without requiring a second purchase. | C6: Client Preview
A7: What changed in v3 | B7: Retained 44 core questions; added three targeted conditional questions. All 69 questions now have five response pathways, risk reasoning and practical next steps. | C7: Questions; Answers; Answer Outcomes
A8: What was already present | B8: V2 had 66 questions, 330 answer choices, broad action triggers and useful first-step action cards. It did not yet provide the full response-specific risk and context layer now added. | C8: Original v2 workbook remains unchanged.
A9: Where to start | B9: Read Client Preview to see the intended outcome. Review Risk Method before changing ratings, then edit Questions, Answers and Action Library for content. | C9: Client Preview; Risk Method
A10: Question catalogue | B10: 44 core plus 25 conditional questions; eight additional unscored context prompts are routed and reused by workstream, not repeated per finding. | C10: Profile & Routes; Risk Context
A11: Customer outcome | B11: What was reported; the concern and reason; provisional risk; action priority; practical steps; owner; relevant timing; completion evidence; recheck trigger. | C11: Answer Outcomes; Risk Register
A12: Score versus risk | B12: The reported-practice score remains separate from risk and urgency. An unresolved essential element can stay High even where the answer earns partial points. | C12: Scoring; Risk Method
A13: Unknown is different | B13: DK receives no demonstrated practice points and remains in the eligible denominator, as in v2. Risk is Unverified; verification can still be High priority. | C13: Answers; Risk Method
A14: Rating status | B14: Low / Medium / High / Critical are proposed triage ratings. Actual likelihood, legal compliance, WHS risk and residual-risk reduction are not established by this questionnaire. | C14: Risk Method; Sources
A15: Timeframe safeguard | B15: Two business days, 30 days and 90 days are proposed response/planning targets, never grace periods. Current harm and earlier duties, decisions or deadlines take precedence. | C15: Risk Method
A16: Working demonstration | B16: Edit Score Sandbox F/G for eligibility and responses. In Risk Register, G:K adds scoped context. Client Preview then changes through formulas. Defaults are fictional. | C16: Score Sandbox; Risk Register
... A24: Original traceability | B24: Current Review and Original Options preserve the original question review and source options. Historical test results are labelled as v2, not claims of v3 validation. | C24: Current Review; Original Options

Sheet Client Preview
A1: Your HR priorities | illustrative report preview
A2: Fictional example driven by Score Sandbox and Risk Register. Read the actions before the score. Ratings reflect reported practices and context, not an independent audit or a finding that the business has breached the law.
A5: Overall position | C5: ='Score Sandbox'!K19 -> Priority review required
A6: Reported-practice score | C6: =IF(ISNUMBER('Score Sandbox'!F21),TEXT('Score Sandbox'!F21,"0.0")&" / 100. This is not a compliance percentage.","Withheld until information or configuration is resolved") -> 91.0 / 100. This is not a compliance percentage.
A7: Risk and action alerts | C7: =COUNTIF('Risk Register'!$N$6:$N$74,4)&" Critical action(s); "&COUNTIF('Risk Register'!$N$6:$N$74,3)&" High-priority action(s). Risk may remain Unverified where the task is to confirm information." -> 0 Critical action(s); 4 High-priority action(s). Risk may remain Unverified where the task is to confirm information.
A8: Unknown information | C8: =TEXT('Score Sandbox'!H19,"0.0%")&" of the domain-weighted assessment is not yet confirmed. Unknown is not the same as absent or unlawful." -> 3.2% of the domain-weighted assessment is not yet confirmed. Unknown is not the same as absent or unlawful.
A9: Immediate safety notice | C9: =IF(COUNTIF('Risk Register'!$G$6:$G$74,"LIVE_HARM")>0,"A serious current exposure has been reported. Take appropriate protective action and seek urgent help now. Do not wait for this assessment to be completed.","No immediate-harm override is selected in this demonstration. This does not establish that the workplace is free of immediate hazards.") -> No immediate-harm override is selected in this demonstration. This does not establish that the workplace is free of immediate hazards.
A11: Critical and High-priority alerts
A12: Priority 1 | C12: =IF($J$12=0,"",IF(INDEX('Risk Register'!$N$6:$N$74,$J$12)<3,"",INDEX('Risk Register'!$O$6:$O$74,$J$12)&" priority | "&INDEX('Risk Register'!$M$6:$M$74,$J$12)&" risk | "&INDEX('Risk Register'!$P$6:$P$74,$J$12))) -> High priority | High risk | Test the payroll result, not just the base rate | J12: =IFERROR(MATCH(1,'Risk Register'!$AA$6:$AA$74,0),0) -> 2
A13: Priority 2 | C13: =IF($J$13=0,"",IF(INDEX('Risk Register'!$N$6:$N$74,$J$13)<3,"",INDEX('Risk Register'!$O$6:$O$74,$J$13)&" priority | "&INDEX('Risk Register'!$M$6:$M$74,$J$13)&" risk | "&INDEX('Risk Register'!$P$6:$P$74,$J$13))) -> High priority | High risk | Reduce reliance on one person | J13: =IFERROR(MATCH(2,'Risk Register'!$AA$6:$AA$74,0),0) -> 29
A14: Priority 3 | C14: =IF($J$14=0,"",IF(INDEX('Risk Register'!$N$6:$N$74,$J$14)<3,"",INDEX('Risk Register'!$O$6:$O$74,$J$14)&" priority | "&INDEX('Risk Register'!$M$6:$M$74,$J$14)&" risk | "&INDEX('Risk Register'!$P$6:$P$74,$J$14))) -> High priority | High risk | Make the reporting route work when power is involved | J14: =IFERROR(MATCH(3,'Risk Register'!$AA$6:$AA$74,0),0) -> 43
A15: Priority 4 | C15: =IF($J$15=0,"",IF(INDEX('Risk Register'!$N$6:$N$74,$J$15)<3,"",INDEX('Risk Register'!$O$6:$O$74,$J$15)&" priority | "&INDEX('Risk Register'!$M$6:$M$74,$J$15)&" risk | "&INDEX('Risk Register'!$P$6:$P$74,$J$15))) -> High priority | Unverified risk | Verify: confirm super reaches the fund | J15: =IFERROR(MATCH(4,'Risk Register'!$AA$6:$AA$74,0),0) -> 4
A16: Priority 5 | C16: =IF($J$16=0,"",IF(INDEX('Risk Register'!$N$6:$N$74,$J$16)<3,"",INDEX('Risk Register'!$O$6:$O$74,$J$16)&" priority | "&INDEX('Risk Register'!$M$6:$M$74,$J$16)&" risk | "&INDEX('Risk Register'!$P$6:$P$74,$J$16))) | J16: =IFERROR(MATCH(5,'Risk Register'!$AA$6:$AA$74,0),0) -> 1
A17: Priority 6 | C17: =IF($J$17=0,"",IF(INDEX('Risk Register'!$N$6:$N$74,$J$17)<3,"",INDEX('Risk Register'!$O$6:$O$74,$J$17)&" priority | "&INDEX('Risk Register'!$M$6:$M$74,$J$17)&" risk | "&INDEX('Risk Register'!$P$6:$P$74,$J$17))) | J17: =IFERROR(MATCH(6,'Risk Register'!$AA$6:$AA$74,0),0) -> 3
A18: Priority 7 | C18: =IF($J$18=0,"",IF(INDEX('Risk Register'!$N$6:$N$74,$J$18)<3,"",INDEX('Risk Register'!$O$6:$O$74,$J$18)&" priority | "&INDEX('Risk Register'!$M$6:$M$74,$J$18)&" risk | "&INDEX('Risk Register'!$P$6:$P$74,$J$18))) | J18: =IFERROR(MATCH(7,'Risk Register'!$AA$6:$AA$74,0),0) -> 6
A19: Priority 8 | C19: =IF($J$19=0,"",IF(INDEX('Risk Register'!$N$6:$N$74,$J$19)<3,"",INDEX('Risk Register'!$O$6:$O$74,$J$19)&" priority | "&INDEX('Risk Register'!$M$6:$M$74,$J$19)&" risk | "&INDEX('Risk Register'!$P$6:$P$74,$J$19))) | J19: =IFERROR(MATCH(8,'Risk Register'!$AA$6:$AA$74,0),0) -> 8
A21: Alert coverage | C21: =IF(COUNTIF('Risk Register'!$N$6:$N$74,">=3")>8,COUNTIF('Risk Register'!$N$6:$N$74,">=3")-8&" additional priority alerts are in Risk Register. This preview does not remove them.","Every Critical / High-priority alert in this example is shown above. The complete register also contains other improvements and maintenance.") -> Every Critical / High-priority alert in this example is shown above. The complete register also contains other improvements and maintenance.
A23: Start with these workstreams
A24: How to use the plan | C24: Choose an owner for each workstream. The lead finding is shown below; keep related findings as separate tasks within it. Complete urgent or legally required action before routine improvements. Suggested targets are not legal grace periods.
A26: Workstream 1 | J26: =IFERROR(MATCH(1,'Risk Register'!$AH$6:$AH$74,0),0) -> 2
A27: Lead finding | C27: =IF($J$26=0,"No further active workstream in this example",INDEX('Risk Register'!$P$6:$P$74,$J$26)) -> Test the payroll result, not just the base rate
A28: Risk / priority | C28: =IF($J$26=0,"",INDEX('Risk Register'!$M$6:$M$74,$J$26)&" provisional risk; "&INDEX('Risk Register'!$O$6:$O$74,$J$26)&" action priority. Basis: "&INDEX('Risk Register'!$K$6:$K$74,$J$26)) -> High provisional risk; High action priority. Basis: Self-report only
A29: Why it matters | C29: =IF($J$26=0,"No further active workstream in this example",INDEX('Risk Register'!$Q$6:$Q$74,$J$26)) -> An unchecked pay rule can repeat across pay periods and employees. The initial gap is lack of assurance, not proof of an underpayment.
A30: Do first | C30: =IF($J$26=0,"No further active workstream in this example",INDEX('Risk Register'!$R$6:$R$74,$J$26)) -> Replace the assumption with a current check. Select representative ordinary and exception pay periods and obtain the actual work records, applicable rules and payslips. Define the arrangements being checked before calculating any difference.
A31: Then | C31: =IF($J$26=0,"No further active workstream in this example",INDEX('Risk Register'!$S$6:$S$74,$J$26)) -> 1. Recalculate selected ordinary and exception pay periods using actual work records. Record differences by entitlement, period and affected arrangement. 2. Investigate the cause of each difference, extend the review where appropriate and test the next affected pay run after correction.
A32: Who owns it | C32: =IF($J$26=0,"No further active workstream in this example",INDEX('Risk Register'!$V$6:$V$74,$J$26)) -> Payroll lead / owner
A33: When to act | C33: =IF($J$26=0,"No further active workstream in this example",INDEX('Risk Register'!$W$6:$W$74,$J$26)) -> Review or verify within 2 business days, or before an earlier duty/event. Do not wait where harm or law requires immediate action.
A34: Finished means | C34: =IF($J$26=0,"No further active workstream in this example",INDEX('Risk Register'!$U$6:$U$74,$J$26)) -> A dated pay-check record for each materially different pay arrangement, with discrepancies investigated, required corrections completed and the next affected pay run checked. Keep any unresolved scope or payment issue open. Confirm that the change works in practice, not only that a document exists.
A35: You reported | C35: =IF($J$26=0,"",INDEX('Answer Outcomes'!$D$6:$D$350,INDEX('Risk Register'!$AF$6:$AF$74,$J$26))) -> We assume our software, payroll provider or above-award rates make the payments correct.
A36: Related findings | C36: =IF($J$26=0,"",INDEX('Risk Register'!$X$6:$X$74,$J$26)&": "&COUNTIFS('Risk Register'!$X$6:$X$74,INDEX('Risk Register'!$X$6:$X$74,$J$26),'Risk Register'!$N$6:$N$74,">1")&" active item(s) in this family. Use Risk Register to retain every child action and exception.") -> PAY_ASSURANCE: 1 active item(s) in this family. Use Risk Register to retain every child action and exception.
A37: Check again | C37: =IF($J$26=0,"No further active workstream in this example",INDEX('Risk Register'!$AC$6:$AC$74,$J$26)) -> A pay-rule change, payroll migration, discrepancy or new work pattern.
A39: Workstream 2 | J39: =IFERROR(MATCH(2,'Risk Register'!$AH$6:$AH$74,0),0) -> 29
A40: Lead finding | C40: =IF($J$39=0,"No further active workstream in this example",INDEX('Risk Register'!$P$6:$P$74,$J$39)) -> Reduce reliance on one person
A41: Risk / priority | C41: =IF($J$39=0,"",INDEX('Risk Register'!$M$6:$M$74,$J$39)&" provisional risk; "&INDEX('Risk Register'!$O$6:$O$74,$J$39)&" action priority. Basis: "&INDEX('Risk Register'!$K$6:$K$74,$J$39)) -> High provisional risk; High action priority. Basis: Self-report only
A42: Why it matters | C42: =IF($J$39=0,"No further active workstream in this example",INDEX('Risk Register'!$Q$6:$Q$74,$J$39)) -> If essential work depends on one unavailable person, payroll, client delivery or approvals can stop even when the rest of the team is capable.
A43: Do first | C43: =IF($J$39=0,"No further active workstream in this example",INDEX('Risk Register'!$R$6:$R$74,$J$39)) -> Replace the assumption with a current check. Choose one business-critical task with no tested backup. Document the essentials and have the nominated backup perform a supervised run-through.
A44: Then | C44: =IF($J$39=0,"No further active workstream in this example",INDEX('Risk Register'!$S$6:$S$74,$J$39)) -> 1. Name a capable backup or external alternative and prepare secure, usable instructions for the critical task. 2. Test the backup without relying on the usual person. Record what failed and retest it.
A45: Who owns it | C45: =IF($J$39=0,"No further active workstream in this example",INDEX('Risk Register'!$V$6:$V$74,$J$39)) -> Owner / people manager
A46: When to act | C46: =IF($J$39=0,"No further active workstream in this example",INDEX('Risk Register'!$W$6:$W$74,$J$39)) -> Review or verify within 2 business days, or before an earlier duty/event. Do not wait where harm or law requires immediate action.
A47: Finished means | C47: =IF($J$39=0,"No further active workstream in this example",INDEX('Risk Register'!$U$6:$U$74,$J$39)) -> A tested cover arrangement for priority tasks, including secure access and authorisations. Confirm that the change works in practice, not only that a document exists.
...

Sheet Questions
A1: Question library | retained core, targeted additions
A2: 44 core questions and 25 conditional questions. Stable IDs retain traceability. Risk consequence is a proposed design judgement, separate from question weight and actual likelihood.
A3: DREAMSTONEHR | PROPOSED V3.0 | 10 OCTOBER 2026
A5: Question ID | B5: Domain | C5: Category | D5: Question | E5: Route | F5: Weight | G5: Critical flag | H5: Answer model | I5: Optional help / interpretation | J5: Original IDs | K5: Action ID | L5: Action family | M5: Source IDs | N5: Primary source URLs | O5: Risk type | P5: Potential consequence class | Q5: Partial answer remains High? | R5: Version note
A6: PAY01 | B6: PAY | C6: Pay & Entitlements | D6: How has your business established which employment rules and classifications apply to each role? | E6: ALL | F6: 3 | G6: Yes | H6: Single choice: 0-3 / DK | I6: Think about the applicable employment system, award or enterprise agreement, and actual duties. A job title or an above-award salary is not enough to decide coverage. | J6: Q01;Q03 | K6: A_PAY01 | L6: PAY_ASSURANCE | M6: S06;S14 | N6: https://www.fairwork.gov.au/pay-and-wages/minimum-wages/annualised-salaries https://www.fairwork.gov.au/tools-and-resources/fact-sheets/rights-and-obligations/record-keeping-pay-slips | O6: Pay and employment rights | P6: 3 | Q6: Yes | R6: Question retained; answer guidance and risk/action pathways developed in v3.
A7: PAY02 | B7: PAY | C7: Pay & Entitlements | D7: How do you check that employees receive the pay and entitlements required for the work they actually perform? | E7: ALL | F7: 3 | G7: Yes | H7: Single choice: 0-3 / DK | I7: Include current rates, ordinary hours, overtime, penalties, breaks and pay frequency where relevant. Outsourced payroll can satisfy this control when the business checks its outputs. | J7: Q04;Q05;Q24;Q47 | K7: A_PAY02 | L7: PAY_ASSURANCE | M7: S06;S07;S14 | N7: https://www.fairwork.gov.au/pay-and-wages/minimum-wages/annualised-salaries https://www.fairwork.gov.au/newsroom/news/offsetting-and-record-keeping-salaried-employees https://www.fairwork.gov.au/tools-and-resources/fact-sheets/rights-and-obligations/record-keeping-pay-slips | O7: Pay and employment rights | P7: 3 | Q7: Yes | R7: Question retained; answer guidance and risk/action pathways developed in v3.
A8: PAY03 | B8: PAY | C8: Pay & Entitlements | D8: How are leave entitlements and payments checked when employment patterns or circumstances change? | E8: ALL | F8: 3 | G8: No | H8: Single choice: 0-3 / DK | I8: Include annual, personal/carer's, parental, compassionate and long service leave, public holidays and relevant loading. Different entitlements have different eligibility and payment rules. | J8: Q02;Q28;Q29;Q37;Q58 | K8: A_PAY03 | L8: LEAVE | M8: S14;S21;S28;S31;S39 | N8: https://www.fairwork.gov.au/tools-and-resources/fact-sheets/rights-and-obligations/record-keeping-pay-slips https://www.fairwork.gov.au/tools-and-resources/fact-sheets/minimum-workplace-entitlements/family-and-domestic-violence-leave https://www.fairwork.gov.au/leave/annual-leave/cashing-out-annual-leave https://www.nsw.gov.au/employment/rights-responsibilities/portable-long-service/csi-long-service-leave-scheme/employer-obligations https://www.fairwork.gov.au/employment-conditions/national-employment-standards | O8: Pay and employment rights | P8: 3 | Q8: No | R8: Question retained; answer guidance and risk/action pathways developed in v3.
A9: PAY04 | B9: PAY | C9: Pay & Entitlements | D9: How do you confirm that required superannuation contributions are calculated correctly and reach employees' funds on time? | E9: ALL | F9: 3 | G9: Yes | H9: Single choice: 0-3 / DK | I9: For earnings paid from 1 July 2026, Payday Super generally requires receipt by the fund, with allocation information, within seven business days after payday; some exceptions apply. Trace receipt rather than submission. Earlier earnings use the applicable earlier rules. | J9: NEW | K9: A_PAY04 | L9: SUPER | M9: S05;S24 | N9: https://www.ato.gov.au/businesses-and-organisations/super-for-employers/paying-super-on-payday/payment-deadlines-for-payday-super https://www.ato.gov.au/businesses-and-organisations/super-for-employers/work-out-if-you-have-to-pay-super/super-for-independent-contractors | O9: Superannuation and financial exposure | P9: 3 | Q9: Yes | R9: B19 legal-test wording clarified; PAY04 timing clarified; response outcomes developed in v3.
A10: PAY05 | B10: PAY | C10: Pay & Entitlements | D10: How do you check the timing and accuracy of employee payslips? | E10: ALL | F10: 2 | G10: No | H10: Single choice: 0-3 / DK | I10: Check required information for the actual pay arrangement, not whether every payslip uses the same layout. Payslips must generally be provided within one working day of payday. | J10: Q22;Q23 | K10: A_PAY05 | L10: PAY_ASSURANCE | M10: S14 | N10: https://www.fairwork.gov.au/tools-and-resources/fact-sheets/rights-and-obligations/record-keeping-pay-slips | O10: Employment records and transparency | P10: 2 | Q10: No | R10: Question retained; answer guidance and risk/action pathways developed in v3.
A11: PAY06 | B11: PAY | C11: Pay & Entitlements | D11: Could your business process paid family and domestic violence leave without exposing the employee's circumstances? | E11: ALL | F11: 3 | G11: Yes | H11: Single choice: 0-3 / DK | I11: Consider the entitlement, payment, evidence handling and payslip description. Assess the process, not whether anyone has disclosed an experience of violence. | J11: Q57 | K11: A_PAY06 | L11: SENSITIVE_LEAVE | M11: S21;S14 | N11: https://www.fairwork.gov.au/tools-and-resources/fact-sheets/minimum-workplace-entitlements/family-and-domestic-violence-leave https://www.fairwork.gov.au/tools-and-resources/fact-sheets/rights-and-obligations/record-keeping-pay-slips | O11: Personal safety and confidential information | P11: 3 | Q11: Yes | R11: Question retained; answer guidance and risk/action pathways developed in v3.
A12: CON01 | B12: CON | C12: Employment Contracts | D12: How reliably do your written employment terms reflect each person's current arrangement? | E12: ALL | F12: 2 | G12: No | H12: Single choice: 0-3 / DK | I12: Look for clear pay, employment type, hours and relevant terms. A longer contract or restrictive clause is not automatically a better contract. | J12: Q13;Q14 | K12: A_CON01 | L12: TERMS | M12: S06;S09 | N12: https://www.fairwork.gov.au/pay-and-wages/minimum-wages/annualised-salaries https://www.fairwork.gov.au/starting-employment/types-of-employees/fixed-term-contract-employees | O12: Employment clarity and disputes | P12: 2 | Q12: No | R12: Question retained; answer guidance and risk/action pathways developed in v3.
A13: CON02 | B13: CON | C13: Employment Contracts | D13: How do you check that each person's employment type reflects the arrangement in practice? | E13: ALL | F13: 3 | G13: No | H13: Single choice: 0-3 / DK | I13: Consider permanent full-time, permanent part-time, casual and fixed-term employment. Use the relevant follow-up where an arrangement needs a more specific check. | J13: Q07 | K13: A_CON02 | L13: TERMS | M13: S03;S09;S23 | N13: https://www.fairwork.gov.au/starting-employment/types-of-employees/casual-employees/becoming-a-permanent-employee https://www.fairwork.gov.au/starting-employment/types-of-employees/fixed-term-contract-employees https://www.fairwork.gov.au/find-help-for/independent-contractors/whole-of-relationship-test | O13: Employment status and entitlements | P13: 3 | Q13: No | R13: Question retained; answer guidance and risk/action pathways developed in v3.
A14: CON03 | B14: CON | C14: Employment Contracts | D14: How are changes to employment terms authorised, communicated and recorded? | E14: ALL | F14: 2 | G14: No | H14: Single choice: 0-3 / DK | I14: Distinguish a contractual change from a routine operational instruction. Identify consent, consultation or instrument requirements before the change. | J14: Q31 | K14: A_CON03 | L14: TERMS | M14: S25;S14 | N14: https://www.fairwork.gov.au/tools-and-resources/best-practice-guides/consultation-and-cooperation-in-the-workplace https://www.fairwork.gov.au/tools-and-resources/fact-sheets/rights-and-obligations/record-keeping-pay-slips | O14: Change control and pay accuracy | P14: 2 | Q14: No | R14: Question retained; answer guidance and risk/action pathways developed in v3.
A15: REC01 | B15: REC | C15: Recruitment & Talent | D15: Before recruiting, how clearly do you define what the role needs to achieve? | E15: ALL | F15: 2 | G15: No | H15: Single choice: 0-3 / DK | I15: A short role brief can be sufficient. Assess clarity of outcomes, essential requirements and responsibilities, not a fixed number of duties. | J15: Q09;Q10 | K15: A_REC01 | L15: HIRING | M15: S01;S27 | N15: https://www.abs.gov.au/statistics/standards/abs-forms-design-standards/2023/general-forms-design-principles-question-structure https://www.fairwork.gov.au/sites/default/files/migration/711/managing-underperformance-best-practice-guide.pdf | O15: Hiring quality and role clarity | P15: 2 | Q15: No | R15: Question retained; answer guidance and risk/action pathways developed in v3.
A16: REC02 | B16: REC | C16: Recruitment & Talent | D16: How do you make recruitment decisions fair, consistent and explainable? | E16: ALL | F16: 2 | G16: No | H16: Single choice: 0-3 / DK | I16: Comparable criteria matter more than mechanically identical conversations. Allow appropriate adjustments and assess evidence relevant to the role. Do not collect sensitive information that is unnecessary for assessing the role requirements. | J16: Q11;Q12 | K16: A_REC02 | L16: HIRING | M16: S01;S15 | N16: https://www.abs.gov.au/statistics/standards/abs-forms-design-standards/2023/general-forms-design-principles-question-structure https://www.oaic.gov.au/privacy/privacy-guidance-for-organisations-and-government-agencies/organisations/employee-records-exemption | O16: Fair selection and explainable decisions | P16: 3 | Q16: No | R16: Question retained; answer guidance and risk/action pathways developed in v3.
A17: REC03 | B17: REC | C17: Recruitment & Talent | D17: How accurately does the recruitment experience describe the job someone is joining? | E17: ALL | F17: 1 | G17: No | H17: Single choice: 0-3 / DK | I17: Consider the advert, interview, offer and communication. Do not score the business on whether every unsuccessful applicant receives a phone call. | J17: Q10;Q12 | K17: A_REC03 | L17: HIRING | M17: S01 | N17: https://www.abs.gov.au/statistics/standards/abs-forms-design-standards/2023/general-forms-design-principles-question-structure | O17: Expectation management and retention | P17: 2 | Q17: No | R17: Question retained; answer guidance and risk/action pathways developed in v3.
... A33: LND02 | B33: LND | C33: Training & Development | D33: How do you check whether training improves performance in the job? | E33: ALL | F33: 2 | G33: No | H33: Single choice: 0-3 / DK | I33: Course attendance is an input. Look for safe application, demonstrated skill, better work or reduced reliance on others. | J33: Q59 | K33: A_LND02 | L33: CAPABILITY | M33: S27 | N33: https://www.fairwork.gov.au/sites/default/files/migration/711/managing-underperformance-best-practice-guide.pdf | O33: Return on development effort | P33: 2 | Q33: No | R33: Question retained; answer guidance and risk/action pathways developed in v3.
A34: LND03 | B34: LND | C34: Training & Development | D34: What would happen to critical work if a key person were unexpectedly unavailable? | E34: ALL | F34: 2 | G34: No | H34: Single choice: 0-3 / DK | I34: Consider payroll, client delivery, approvals and specialist knowledge. This does not require a formal succession programme. | J34: Q59 | K34: A_LND03 | L34: CAPABILITY | M34: DESIGN | O34: Business continuity | P34: 3 | Q34: No | R34: Question retained; answer guidance and risk/action pathways developed in v3.
A35: CUL01 | B35: CUL | C35: Culture & Engagement | D35: How do you learn what employees experience at work and show what happens to their feedback? | E35: ALL | F35: 2 | G35: No | H35: Single choice: 0-3 / DK | I35: Use a method suitable for your size. A manager's positive view of the culture is not a substitute for employee input; a five-person survey is not necessarily anonymous. | J35: Q50 | K35: A_CUL01 | L35: CULTURE | M35: S25;S10 | N35: https://www.fairwork.gov.au/tools-and-resources/best-practice-guides/consultation-and-cooperation-in-the-workplace https://humanrights.gov.au/resource-hub/resources-for-organisations-businesses/positive-duty-pdfs/guidelines-for-complying-with-the-positive-duty-under-the-sex-discrimination-act-1984-cth | O35: Employee voice and follow-through | P35: 2 | Q35: No | R35: Question retained; answer guidance and risk/action pathways developed in v3.
A36: CUL02 | B36: CUL | C36: Culture & Engagement | D36: How do you understand and respond to the risk of losing employees you would prefer to retain? | E36: ALL | F36: 2 | G36: No | H36: Single choice: 0-3 / DK | I36: For a small team, consider individual retention concerns and departures rather than volatile percentages. If nobody has left recently, assess the way you identify and respond to retention concerns. | J36: Q48;Q47 | K36: A_CUL02 | L36: CULTURE | M36: DESIGN | O36: Retention and service continuity | P36: 2 | Q36: No | R36: Question retained; answer guidance and risk/action pathways developed in v3.
A37: CUL03 | B37: CUL | C37: Culture & Engagement | D37: How do employees see that contribution and opportunity are recognised fairly? | E37: ALL | F37: 1 | G37: No | H37: Single choice: 0-3 / DK | I37: Recognition need not involve spending money or organising events. Consider everyday feedback, allocation of opportunities and treatment of different work patterns. | J37: Q49;Q50 | K37: A_CUL03 | L37: CULTURE | M37: S10;S11 | N37: https://humanrights.gov.au/resource-hub/resources-for-organisations-businesses/positive-duty-pdfs/guidelines-for-complying-with-the-positive-duty-under-the-sex-discrimination-act-1984-cth https://www.safeworkaustralia.gov.au/safety-topic/managing-health-and-safety/mental-health/managing-risks/identifying-assessing-controlling-and-reviewing | O37: Fair opportunity and recognition | P37: 1 | Q37: No | R37: Question retained; answer guidance and risk/action pathways developed in v3.
A38: CUL04 | B38: CUL | C38: Culture & Engagement | D38: How do you hold people leaders accountable for the way they manage others? | E38: ALL | F38: 2 | G38: No | H38: Single choice: 0-3 / DK | I38: The owner is a people leader too. In an owner-managed business, employee feedback and periodic review of actual decisions can provide accountability; a formal management appraisal is not required. | J38: NEW | K38: A_CUL04 | L38: LEADERSHIP | M38: S10;S27 | N38: https://humanrights.gov.au/resource-hub/resources-for-organisations-businesses/positive-duty-pdfs/guidelines-for-complying-with-the-positive-duty-under-the-sex-discrimination-act-1984-cth https://www.fairwork.gov.au/sites/default/files/migration/711/managing-underperformance-best-practice-guide.pdf | O38: Leadership accountability | P38: 2 | Q38: No | R38: Question retained; answer guidance and risk/action pathways developed in v3.
A39: DAT01 | B39: DAT | C39: Record Keeping | D39: Could you reconstruct an employee's pay and entitlements from the records you keep? | E39: ALL | F39: 3 | G39: Yes | H39: Single choice: 0-3 / DK | I39: Include actual work and overtime where required, leave, changes, deductions and relevant approvals. A roster is not proof that actual hours matched it. Statutory record requirements vary by arrangement. | J39: Q21;Q27;Q37 | K39: A_DAT01 | L39: PAY_ASSURANCE | M39: S14;S07 | N39: https://www.fairwork.gov.au/tools-and-resources/fact-sheets/rights-and-obligations/record-keeping-pay-slips https://www.fairwork.gov.au/newsroom/news/offsetting-and-record-keeping-salaried-employees | O39: Pay records and evidentiary reliability | P39: 3 | Q39: Yes | R39: Question retained; answer guidance and risk/action pathways developed in v3.
A40: DAT02 | B40: DAT | C40: Record Keeping | D40: How do you protect employee and applicant information from unnecessary access or use? | E40: ALL | F40: 3 | G40: No | H40: Single choice: 0-3 / DK | I40: Consider collection, access, sharing, retention and deletion, including external providers. Privacy Act coverage and the employee-records exemption require separate assessment. | J40: Q27;Q12 | K40: A_DAT02 | L40: INFORMATION | M40: S15;S16;S17 | N40: https://www.oaic.gov.au/privacy/privacy-guidance-for-organisations-and-government-agencies/organisations/employee-records-exemption https://www.oaic.gov.au/privacy/privacy-guidance-for-organisations-and-government-agencies/organisations/small-business https://www.oaic.gov.au/news/media-centre/new-resources-on-transparency-for-use-of-ai-and-automated-decision-making | O40: Privacy and confidential information | P40: 3 | Q40: Yes | R40: Question retained; answer guidance and risk/action pathways developed in v3.
A41: DAT03 | B41: DAT | C41: Record Keeping | D41: Could the business retrieve essential people records if its usual administrator or system were unavailable? | E41: ALL | F41: 2 | G41: No | H41: Single choice: 0-3 / DK | I41: Consider authorised backup access, export capability, version control and a tested recovery method. Do not share personal passwords. | J41: Q27 | K41: A_DAT03 | L41: INFORMATION | M41: S14;S15 | N41: https://www.fairwork.gov.au/tools-and-resources/fact-sheets/rights-and-obligations/record-keeping-pay-slips https://www.oaic.gov.au/privacy/privacy-guidance-for-organisations-and-government-agencies/organisations/employee-records-exemption | O41: Record availability and continuity | P41: 3 | Q41: No | R41: Question retained; answer guidance and risk/action pathways developed in v3.
A42: EXT01 | B42: EXT | C42: Employee Exits | D42: Before ending employment, how do you check the reason, required process and protections that may apply? | E42: ALL | F42: 3 | G42: Yes | H42: Single choice: 0-3 / DK | I42: Include employees in probation and small businesses. Knowing how to defend a claim is not the same as making a sound decision before one arises. | J42: Q38;Q40;Q46;Q52;Q63;Q64 | K42: A_EXT01 | L42: FAIR_DECISIONS | M42: S02;S26 | N42: https://www.fairwork.gov.au/taxonomy/term/527 https://www.fairwork.gov.au/tools-and-resources/fact-sheets/minimum-workplace-entitlements/ending-employment | O42: Employment-ending decisions | P42: 3 | Q42: Yes | R42: Question retained; answer guidance and risk/action pathways developed in v3.
A43: EXT02 | B43: EXT | C43: Employee Exits | D43: How do you check final pay and employment documentation when a person leaves? | E43: ALL | F43: 3 | G43: No | H43: Single choice: 0-3 / DK | I43: Check the applicable notice, leave, redundancy where relevant, payment timing and permitted deductions. Different exit reasons can produce different entitlements. | J43: Q46 | K43: A_EXT02 | L43: EXIT | M43: S26;S08;S14 | N43: https://www.fairwork.gov.au/tools-and-resources/fact-sheets/minimum-workplace-entitlements/ending-employment https://www.fairwork.gov.au/pay-and-wages/deductions-and-related-issues/deducting-pay https://www.fairwork.gov.au/tools-and-resources/fact-sheets/rights-and-obligations/record-keeping-pay-slips | O43: Final pay and entitlements | P43: 3 | Q43: No | R43: Question retained; answer guidance and risk/action pathways developed in v3.
A44: EXT03 | B44: EXT | C44: Employee Exits | D44: How do you protect continuity and information when an employee leaves? | E44: ALL | F44: 2 | G44: No | H44: Single choice: 0-3 / DK | I44: Consider the timing of access changes, return of property, transfer of work and preservation of relevant records. Do not make payment conditional on property return without checking the law. | J44: NEW | K44: A_EXT03 | L44: EXIT | M44: S14;S15;S08 | N44: https://www.fairwork.gov.au/tools-and-resources/fact-sheets/rights-and-obligations/record-keeping-pay-slips https://www.oaic.gov.au/privacy/privacy-guidance-for-organisations-and-government-agencies/organisations/employee-records-exemption https://www.fairwork.gov.au/pay-and-wages/deductions-and-related-issues/deducting-pay | O44: Access, records and continuity | P44: 3 | Q44: No | R44: Question retained; answer guidance and risk/action pathways developed in v3.
A45: PSY01 | B45: PSY | C45: Psychosocial Risk & Positive Duty | D45: How do you identify aspects of work that could harm people's psychological health? | E45: ALL | F45: 3 | G45: Yes | H45: Single choice: 0-3 / DK | I45: Consider workload, role clarity, support, change, isolation, aggression and other work-related hazards. Seek input from workers rather than waiting for a formal complaint. | J45: Q50;Q60;Q62 | K45: A_PSY01 | L45: PSYCHOSOCIAL | M45: S11;S12 | N45: https://www.safeworkaustralia.gov.au/safety-topic/managing-health-and-safety/mental-health/managing-risks/identifying-assessing-controlling-and-reviewing https://www.safeworkaustralia.gov.au/safety-topic/managing-health-and-safety/mental-health/managing-risks/differences-between-whs-and-wellbeing | O45: Work-related psychological harm | P45: 3 | Q45: Yes | R45: Question retained; answer guidance and risk/action pathways developed in v3.
A46: PSY02 | B46: PSY | C46: Psychosocial Risk & Positive Duty | D46: What arrangements control the psychosocial risks arising from your work? | E46: ALL | F46: 3 | G46: Yes | H46: Single choice: 0-3 / DK | I46: Look for controls addressing workload, staffing, role design, supervision or aggression. Controls may already be built into how work is organised. Support services do not replace prevention; a new programme is not automatically required. | J46: Q60;Q62 | K46: A_PSY02 | L46: PSYCHOSOCIAL | M46: S11;S12 | N46: https://www.safeworkaustralia.gov.au/safety-topic/managing-health-and-safety/mental-health/managing-risks/identifying-assessing-controlling-and-reviewing https://www.safeworkaustralia.gov.au/safety-topic/managing-health-and-safety/mental-health/managing-risks/differences-between-whs-and-wellbeing | O46: Work-related psychological harm | P46: 3 | Q46: Yes | R46: Question retained; answer guidance and risk/action pathways developed in v3.
A47: PSY03 | B47: PSY | C47: Psychosocial Risk & Positive Duty | D47: How does your business actively prevent sexual harassment, sex-based harassment and related unlawful conduct? | E47: ALL | F47: 3 | G47: Yes | H47: Single choice: 0-3 / DK | I47: Consider the positive duty under the Sex Discrimination Act, including sex discrimination, hostile environments on the ground of sex and related victimisation. This duty is related to, but distinct from, general WHS duties. | J47: Q56 | K47: A_PSY03 | L47: RESPECT | M47: S10 | N47: https://humanrights.gov.au/resource-hub/resources-for-organisations-businesses/positive-duty-pdfs/guidelines-for-complying-with-the-positive-duty-under-the-sex-discrimination-act-1984-cth | O47: Prevention of unlawful workplace conduct | P47: 3 | Q47: Yes | R47: Question retained; answer guidance and risk/action pathways developed in v3.
A48: PSY04 | B48: PSY | C48: Psychosocial Risk & Positive Duty | D48: Could someone raise a concern safely if it involved their manager, the owner or a high-performing colleague? | E48: ALL | F48: 3 | G48: Yes | H48: Single choice: 0-3 / DK | I48: A reporting route must work when the usual contact is the subject of the concern. Do not promise anonymity where it cannot be delivered. | J48: Q56;Q50 | K48: A_PSY04 | L48: RESPECT | M48: S10;S11 | N48: https://humanrights.gov.au/resource-hub/resources-for-organisations-businesses/positive-duty-pdfs/guidelines-for-complying-with-the-positive-duty-under-the-sex-discrimination-act-1984-cth https://www.safeworkaustralia.gov.au/safety-topic/managing-health-and-safety/mental-health/managing-risks/identifying-assessing-controlling-and-reviewing | O48: Safe reporting and protection from retaliation | P48: 3 | Q48: Yes | R48: Question retained; answer guidance and risk/action pathways developed in v3.
... A74: B25 | B74: WHS | C74: Workplace Health & Safety | D74: How do you coordinate safety responsibilities when people work through a labour-hire or other shared-work arrangement? | E74: SHARED_WORK | F74: 3 | G74: Yes | H74: Single choice: 0-3 / DK | I74: Use for labour-hire placements or other work involving overlapping duty holders. Record who performs each safety task, but do not assume duties can be contracted away. Confirm applicable state or territory requirements. | J74: NEW v3 | K74: A_B25 | L74: SHARED_SAFETY | M74: S42;S13;S38 | N74: https://www.safeworkaustralia.gov.au/safety-topic/managing-health-and-safety/labour-hire/whs-duties https://www.safeworkaustralia.gov.au/safety-topic/managing-health-and-safety/identify-assess-and-control-hazards/managing-risks https://www.safeworkaustralia.gov.au/workers-compensation | O74: Shared work health and safety duties | P74: 3 | Q74: Yes | R74: New conditional question in v3

Sheet Answers
A1: Answer choices | practical detail without longer questions
A2: Four specific maturity choices plus an explicit unknown. Optional answer help supports an honest choice; evidence is requested as a type or example, not uploaded into a general assessment.
A3: DREAMSTONEHR | PROPOSED V3.0 | 10 OCTOBER 2026
A5: Question ID | B5: Answer ID | C5: Response code | D5: Scoring points | E5: Customer-facing answer | F5: Meaning | G5: Result handling | H5: Eligibility rule | I5: Help choosing this answer | J5: Evidence the business should be able to locate | K5: Outcome key
A6: PAY01 | B6: PAY01_0 | C6: 0 | D6: 0 | E6: We have not checked which rules apply to our roles. | F6: Practice absent or not established as described | G6: Outcome PAY01_0 supplies provisional risk, priority, reasons and actions. Apply contextual escalation separately. | H6: Confirmed exclusion only; DK retains the eligible denominator. | I6: Choose this when the statement describes the current position. Reporting a gap helps prioritise support; it is not an admission that a legal breach has occurred. | J6: A dated coverage and classification record with reasons for every distinct role, appropriate review of uncertain classifications, and resulting payroll changes checked. An unresolved classification remains an open task. | K6: PAY01_0
A7: PAY01 | B7: PAY01_1 | C7: 1 | D7: 1 | E7: We rely on job titles, past practice or payroll defaults, without a recorded coverage check. | F7: Assumption-dependent or inconsistent practice | G7: Outcome PAY01_1 supplies provisional risk, priority, reasons and actions. Apply contextual escalation separately. | H7: Confirmed exclusion only; DK retains the eligible denominator. | I7: Choose this when the process depends on assumptions, personal knowledge or ad hoc handling rather than a dependable check. | J7: A dated coverage and classification record with reasons for every distinct role, appropriate review of uncertain classifications, and resulting payroll changes checked. An unresolved classification remains an open task. | K7: PAY01_1
A8: PAY01 | B8: PAY01_2 | C8: 2 | D8: 2 | E8: We have checked some roles, but changes or exceptions remain unresolved. | F8: Partly established; residual gap remains | G8: Outcome PAY01_2 supplies provisional risk, priority, reasons and actions. Apply contextual escalation separately. | H8: Confirmed exclusion only; DK retains the eligible denominator. | I8: Choose this when important parts exist but at least one part of the statement remains unresolved. The report should target that gap, not require a full rebuild. | J8: A dated coverage and classification record with reasons for every distinct role, appropriate review of uncertain classifications, and resulting payroll changes checked. An unresolved classification remains an open task. | K8: PAY01_2
A9: PAY01 | B9: PAY01_3 | C9: 3 | D9: 3 | E9: We have a current record for every role, including the basis for any award-free classification, and review it when duties change. | F9: Established practice reported, not independently verified | G9: Outcome PAY01_3 supplies provisional risk, priority, reasons and actions. Apply contextual escalation separately. | H9: Confirmed exclusion only; DK retains the eligible denominator. | I9: Choose this only when the whole statement describes routine practice and you can point to a recent example or a tested readiness process. One successful exception is not enough. | J9: A dated coverage and classification record with reasons for every distinct role, appropriate review of uncertain classifications, and resulting payroll changes checked. An unresolved classification remains an open task. | K9: PAY01_3
A10: PAY01 | B10: PAY01_DK | C10: DK | D10: 0 | E10: I need to confirm this. | F10: Unverified, not an established failure | G10: Outcome PAY01_DK supplies provisional risk, priority, reasons and actions. Apply contextual escalation separately. | H10: Confirmed exclusion only; DK retains the eligible denominator. | I10: Choose this rather than guessing when you cannot confirm the practice or its consistency. You can save the assessment and ask the responsible person. | J10: A dated coverage and classification record with reasons for every distinct role, appropriate review of uncertain classifications, and resulting payroll changes checked. An unresolved classification remains an open task. | K10: PAY01_DK
A11: PAY02 | B11: PAY02_0 | C11: 0 | D11: 0 | E11: We have not checked payroll against actual work and applicable rules. | F11: Practice absent or not established as described | G11: Outcome PAY02_0 supplies provisional risk, priority, reasons and actions. Apply contextual escalation separately. | H11: Confirmed exclusion only; DK retains the eligible denominator. | I11: Choose this when the statement describes the current position. Reporting a gap helps prioritise support; it is not an admission that a legal breach has occurred. | J11: A dated pay-check record for each materially different pay arrangement, with discrepancies investigated, required corrections completed and the next affected pay run checked. Keep any unresolved scope or payment issue open. | K11: PAY02_0
A12: PAY02 | B12: PAY02_1 | C12: 1 | D12: 1 | E12: We assume our software, payroll provider or above-award rates make the payments correct. | F12: Assumption-dependent or inconsistent practice | G12: Outcome PAY02_1 supplies provisional risk, priority, reasons and actions. Apply contextual escalation separately. | H12: Confirmed exclusion only; DK retains the eligible denominator. | I12: Choose this when the process depends on assumptions, personal knowledge or ad hoc handling rather than a dependable check. | J12: A dated pay-check record for each materially different pay arrangement, with discrepancies investigated, required corrections completed and the next affected pay run checked. Keep any unresolved scope or payment issue open. | K12: PAY02_1
A13: PAY02 | B13: PAY02_2 | C13: 2 | D13: 2 | E13: We check base rates, but some working patterns or other entitlements have not been tested. | F13: Partly established; residual gap remains | G13: Outcome PAY02_2 supplies provisional risk, priority, reasons and actions. Apply contextual escalation separately. | H13: Confirmed exclusion only; DK retains the eligible denominator. | I13: Choose this when important parts exist but at least one part of the statement remains unresolved. The report should target that gap, not require a full rebuild. | J13: A dated pay-check record for each materially different pay arrangement, with discrepancies investigated, required corrections completed and the next affected pay run checked. Keep any unresolved scope or payment issue open. | K13: PAY02_2
A14: PAY02 | B14: PAY02_3 | C14: 3 | D14: 3 | E14: We check representative actual pay periods against applicable rules, document exceptions and verify that corrections are completed. | F14: Established practice reported, not independently verified | G14: Outcome PAY02_3 supplies provisional risk, priority, reasons and actions. Apply contextual escalation separately. | H14: Confirmed exclusion only; DK retains the eligible denominator. | I14: Choose this only when the whole statement describes routine practice and you can point to a recent example or a tested readiness process. One successful exception is not enough. | J14: A dated pay-check record for each materially different pay arrangement, with discrepancies investigated, required corrections completed and the next affected pay run checked. Keep any unresolved scope or payment issue open. | K14: PAY02_3
A15: PAY02 | B15: PAY02_DK | C15: DK | D15: 0 | E15: I need to confirm this. | F15: Unverified, not an established failure | G15: Outcome PAY02_DK supplies provisional risk, priority, reasons and actions. Apply contextual escalation separately. | H15: Confirmed exclusion only; DK retains the eligible denominator. | I15: Choose this rather than guessing when you cannot confirm the practice or its consistency. You can save the assessment and ask the responsible person. | J15: A dated pay-check record for each materially different pay arrangement, with discrepancies investigated, required corrections completed and the next affected pay run checked. Keep any unresolved scope or payment issue open. | K15: PAY02_DK
A16: PAY03 | B16: PAY03_0 | C16: 0 | D16: 0 | E16: Leave is handled without a consistent check of eligibility, balances or pay. | F16: Practice absent or not established as described | G16: Outcome PAY03_0 supplies provisional risk, priority, reasons and actions. Apply contextual escalation separately. | H16: Confirmed exclusion only; DK retains the eligible denominator. | I16: Choose this when the statement describes the current position. Reporting a gap helps prioritise support; it is not an admission that a legal breach has occurred. | J16: A dated leave reconciliation against the applicable rules, with incorrect balances or payments corrected and a follow-up transaction checked. State-based and instrument-specific matters are resolved or remain clearly open. | K16: PAY03_0
A17: PAY03 | B17: PAY03_1 | C17: 1 | D17: 1 | E17: We use the default payroll settings and deal with exceptions as they arise. | F17: Assumption-dependent or inconsistent practice | G17: Outcome PAY03_1 supplies provisional risk, priority, reasons and actions. Apply contextual escalation separately. | H17: Confirmed exclusion only; DK retains the eligible denominator. | I17: Choose this when the process depends on assumptions, personal knowledge or ad hoc handling rather than a dependable check. | J17: A dated leave reconciliation against the applicable rules, with incorrect balances or payments corrected and a follow-up transaction checked. State-based and instrument-specific matters are resolved or remain clearly open. | K17: PAY03_1
A18: PAY03 | B18: PAY03_2 | C18: 2 | D18: 2 | E18: Most leave is checked, but some employment types, jurisdictions or changes need review. | F18: Partly established; residual gap remains | G18: Outcome PAY03_2 supplies provisional risk, priority, reasons and actions. Apply contextual escalation separately. | H18: Confirmed exclusion only; DK retains the eligible denominator. | I18: Choose this when important parts exist but at least one part of the statement remains unresolved. The report should target that gap, not require a full rebuild. | J18: A dated leave reconciliation against the applicable rules, with incorrect balances or payments corrected and a follow-up transaction checked. State-based and instrument-specific matters are resolved or remain clearly open. | K18: PAY03_2
A19: PAY03 | B19: PAY03_3 | C19: 3 | D19: 3 | E19: We check the applicable entitlement and payment, maintain accurate balances and review settings when hours, service or rules change. | F19: Established practice reported, not independently verified | G19: Outcome PAY03_3 supplies provisional risk, priority, reasons and actions. Apply contextual escalation separately. | H19: Confirmed exclusion only; DK retains the eligible denominator. | I19: Choose this only when the whole statement describes routine practice and you can point to a recent example or a tested readiness process. One successful exception is not enough. | J19: A dated leave reconciliation against the applicable rules, with incorrect balances or payments corrected and a follow-up transaction checked. State-based and instrument-specific matters are resolved or remain clearly open. | K19: PAY03_3
A20: PAY03 | B20: PAY03_DK | C20: DK | D20: 0 | E20: I need to confirm this. | F20: Unverified, not an established failure | G20: Outcome PAY03_DK supplies provisional risk, priority, reasons and actions. Apply contextual escalation separately. | H20: Confirmed exclusion only; DK retains the eligible denominator. | I20: Choose this rather than guessing when you cannot confirm the practice or its consistency. You can save the assessment and ask the responsible person. | J20: A dated leave reconciliation against the applicable rules, with incorrect balances or payments corrected and a follow-up transaction checked. State-based and instrument-specific matters are resolved or remain clearly open. | K20: PAY03_DK
A21: PAY04 | B21: PAY04_0 | C21: 0 | D21: 0 | E21: We are not consistently paying required superannuation by the applicable deadline. | F21: Practice absent or not established as described | G21: Outcome PAY04_0 supplies provisional risk, priority, reasons and actions. Apply contextual escalation separately. | H21: Confirmed exclusion only; DK retains the eligible denominator. | I21: Choose this when the statement describes the current position. Reporting a gap helps prioritise support; it is not an admission that a legal breach has occurred. | J21: A contribution reconciliation showing actual fund receipt and any missed deadline, with shortfalls, rejected payments and related obligations addressed. A subsequent cycle demonstrates timely receipt; later correction does not erase an earlier delay. | K21: PAY04_0
A22: PAY04 | B22: PAY04_1 | C22: 1 | D22: 1 | E22: We rely on payroll or clearing-house submissions without checking rejected or late contributions. | F22: Assumption-dependent or inconsistent practice | G22: Outcome PAY04_1 supplies provisional risk, priority, reasons and actions. Apply contextual escalation separately. | H22: Confirmed exclusion only; DK retains the eligible denominator. | I22: Choose this when the process depends on assumptions, personal knowledge or ad hoc handling rather than a dependable check. | J22: A contribution reconciliation showing actual fund receipt and any missed deadline, with shortfalls, rejected payments and related obligations addressed. A subsequent cycle demonstrates timely receipt; later correction does not erase an earlier delay. | K22: PAY04_1
A23: PAY04 | B23: PAY04_2 | C23: 2 | D23: 2 | E23: We check payments, but some earnings, fund exceptions or receipt dates are unresolved. | F23: Partly established; residual gap remains | G23: Outcome PAY04_2 supplies provisional risk, priority, reasons and actions. Apply contextual escalation separately. | H23: Confirmed exclusion only; DK retains the eligible denominator. | I23: Choose this when important parts exist but at least one part of the statement remains unresolved. The report should target that gap, not require a full rebuild. | J23: A contribution reconciliation showing actual fund receipt and any missed deadline, with shortfalls, rejected payments and related obligations addressed. A subsequent cycle demonstrates timely receipt; later correction does not erase an earlier delay. | K23: PAY04_2
A24: PAY04 | B24: PAY04_3 | C24: 3 | D24: 3 | E24: We reconcile the applicable earnings, rate and fund receipt, and promptly resolve rejected or late contributions. | F24: Established practice reported, not independently verified | G24: Outcome PAY04_3 supplies provisional risk, priority, reasons and actions. Apply contextual escalation separately. | H24: Confirmed exclusion only; DK retains the eligible denominator. | I24: Choose this only when the whole statement describes routine practice and you can point to a recent example or a tested readiness process. One successful exception is not enough. | J24: A contribution reconciliation showing actual fund receipt and any missed deadline, with shortfalls, rejected payments and related obligations addressed. A subsequent cycle demonstrates timely receipt; later correction does not erase an earlier delay. | K24: PAY04_3
A25: PAY04 | B25: PAY04_DK | C25: DK | D25: 0 | E25: I need to confirm this. | F25: Unverified, not an established failure | G25: Outcome PAY04_DK supplies provisional risk, priority, reasons and actions. Apply contextual escalation separately. | H25: Confirmed exclusion only; DK retains the eligible denominator. | I25: Choose this rather than guessing when you cannot confirm the practice or its consistency. You can save the assessment and ask the responsible person. | J25: A contribution reconciliation showing actual fund receipt and any missed deadline, with shortfalls, rejected payments and related obligations addressed. A subsequent cycle demonstrates timely receipt; later correction does not erase an earlier delay. | K25: PAY04_DK
A26: PAY05 | B26: PAY05_0 | C26: 0 | D26: 0 | E26: Payslips are not consistently provided. | F26: Practice absent or not established as described | G26: Outcome PAY05_0 supplies provisional risk, priority, reasons and actions. Apply contextual escalation separately. | H26: Confirmed exclusion only; DK retains the eligible denominator. | I26: Choose this when the statement describes the current position. Reporting a gap helps prioritise support; it is not an admission that a legal breach has occurred. | J26: A completed payslip check, required corrections issued, delivery/access confirmed and a subsequent payslip checked. Preserve the original record and how any past failure was addressed. | K26: PAY05_0
A27: PAY05 | B27: PAY05_1 | C27: 1 | D27: 1 | E27: Payslips are produced, but timing or required fields have not been checked. | F27: Assumption-dependent or inconsistent practice | G27: Outcome PAY05_1 supplies provisional risk, priority, reasons and actions. Apply contextual escalation separately. | H27: Confirmed exclusion only; DK retains the eligible denominator. | I27: Choose this when the process depends on assumptions, personal knowledge or ad hoc handling rather than a dependable check. | J27: A completed payslip check, required corrections issued, delivery/access confirmed and a subsequent payslip checked. Preserve the original record and how any past failure was addressed. | K27: PAY05_1
A28: PAY05 | B28: PAY05_2 | C28: 2 | D28: 2 | E28: Timing and most details are correct, but some arrangements or exceptions need checking. | F28: Partly established; residual gap remains | G28: Outcome PAY05_2 supplies provisional risk, priority, reasons and actions. Apply contextual escalation separately. | H28: Confirmed exclusion only; DK retains the eligible denominator. | I28: Choose this when important parts exist but at least one part of the statement remains unresolved. The report should target that gap, not require a full rebuild. | J28: A completed payslip check, required corrections issued, delivery/access confirmed and a subsequent payslip checked. Preserve the original record and how any past failure was addressed. | K28: PAY05_2
A29: PAY05 | B29: PAY05_3 | C29: 3 | D29: 3 | E29: We have checked timing, required fields and secure employee access across our pay arrangements. | F29: Established practice reported, not independently verified | G29: Outcome PAY05_3 supplies provisional risk, priority, reasons and actions. Apply contextual escalation separately. | H29: Confirmed exclusion only; DK retains the eligible denominator. | I29: Choose this only when the whole statement describes routine practice and you can point to a recent example or a tested readiness process. One successful exception is not enough. | J29: A completed payslip check, required corrections issued, delivery/access confirmed and a subsequent payslip checked. Preserve the original record and how any past failure was addressed. | K29: PAY05_3
A30: PAY05 | B30: PAY05_DK | C30: DK | D30: 0 | E30: I need to confirm this. | F30: Unverified, not an established failure | G30: Outcome PAY05_DK supplies provisional risk, priority, reasons and actions. Apply contextual escalation separately. | H30: Confirmed exclusion only; DK retains the eligible denominator. | I30: Choose this rather than guessing when you cannot confirm the practice or its consistency. You can save the assessment and ask the responsible person. | J30: A completed payslip check, required corrections issued, delivery/access confirmed and a subsequent payslip checked. Preserve the original record and how any past failure was addressed. | K30: PAY05_DK
A31: PAY06 | B31: PAY06_0 | C31: 0 | D31: 0 | E31: We do not have a process for this leave. | F31: Practice absent or not established as described | G31: Outcome PAY06_0 supplies provisional risk, priority, reasons and actions. Apply contextual escalation separately. | H31: Confirmed exclusion only; DK retains the eligible denominator. | I31: Choose this when the statement describes the current position. Reporting a gap helps prioritise support; it is not an admission that a legal breach has occurred. | J31: A tested confidential workflow and fictional payslip, with a named contact for employees. | K31: PAY06_0
